[2023-03-16T05:01:08.869+0000] {taskinstance.py:1083} INFO - Dependencies all met for <TaskInstance: Spotify_Data_ETL.GetArtistInfo manual__2023-03-16T04:25:58.412323+00:00 [queued]>
[2023-03-16T05:01:08.874+0000] {taskinstance.py:1083} INFO - Dependencies all met for <TaskInstance: Spotify_Data_ETL.GetArtistInfo manual__2023-03-16T04:25:58.412323+00:00 [queued]>
[2023-03-16T05:01:08.874+0000] {taskinstance.py:1279} INFO - 
--------------------------------------------------------------------------------
[2023-03-16T05:01:08.874+0000] {taskinstance.py:1280} INFO - Starting attempt 6 of 8
[2023-03-16T05:01:08.875+0000] {taskinstance.py:1281} INFO - 
--------------------------------------------------------------------------------
[2023-03-16T05:01:08.885+0000] {taskinstance.py:1300} INFO - Executing <Task(PythonOperator): GetArtistInfo> on 2023-03-16 04:25:58.412323+00:00
[2023-03-16T05:01:08.891+0000] {standard_task_runner.py:55} INFO - Started process 8332 to run task
[2023-03-16T05:01:08.895+0000] {standard_task_runner.py:82} INFO - Running: ['***', 'tasks', 'run', 'Spotify_Data_ETL', 'GetArtistInfo', 'manual__2023-03-16T04:25:58.412323+00:00', '--job-id', '1158', '--raw', '--subdir', 'DAGS_FOLDER/spotifydag.py', '--cfg-path', '/tmp/tmps1gvbfke']
[2023-03-16T05:01:08.896+0000] {standard_task_runner.py:83} INFO - Job 1158: Subtask GetArtistInfo
[2023-03-16T05:01:08.974+0000] {task_command.py:388} INFO - Running <TaskInstance: Spotify_Data_ETL.GetArtistInfo manual__2023-03-16T04:25:58.412323+00:00 [running]> on host 18c42e4ef76b
[2023-03-16T05:01:09.294+0000] {taskinstance.py:1509} INFO - Exporting the following env vars:
AIRFLOW_CTX_DAG_OWNER=Ananta Moharana
AIRFLOW_CTX_DAG_ID=Spotify_Data_ETL
AIRFLOW_CTX_TASK_ID=GetArtistInfo
AIRFLOW_CTX_EXECUTION_DATE=2023-03-16T04:25:58.412323+00:00
AIRFLOW_CTX_TRY_NUMBER=6
AIRFLOW_CTX_DAG_RUN_ID=manual__2023-03-16T04:25:58.412323+00:00
[2023-03-16T05:01:44.896+0000] {taskinstance.py:1768} ERROR - Task failed with exception
Traceback (most recent call last):
  File "/home/airflow/.local/lib/python3.7/site-packages/urllib3/connectionpool.py", line 710, in urlopen
    chunked=chunked,
  File "/home/airflow/.local/lib/python3.7/site-packages/urllib3/connectionpool.py", line 449, in _make_request
    six.raise_from(e, None)
  File "<string>", line 3, in raise_from
  File "/home/airflow/.local/lib/python3.7/site-packages/urllib3/connectionpool.py", line 444, in _make_request
    httplib_response = conn.getresponse()
  File "/usr/local/lib/python3.7/http/client.py", line 1373, in getresponse
    response.begin()
  File "/usr/local/lib/python3.7/http/client.py", line 319, in begin
    version, status, reason = self._read_status()
  File "/usr/local/lib/python3.7/http/client.py", line 288, in _read_status
    raise RemoteDisconnected("Remote end closed connection without"
http.client.RemoteDisconnected: Remote end closed connection without response

During handling of the above exception, another exception occurred:

Traceback (most recent call last):
  File "/home/airflow/.local/lib/python3.7/site-packages/requests/adapters.py", line 499, in send
    timeout=timeout,
  File "/home/airflow/.local/lib/python3.7/site-packages/urllib3/connectionpool.py", line 788, in urlopen
    method, url, error=e, _pool=self, _stacktrace=sys.exc_info()[2]
  File "/home/airflow/.local/lib/python3.7/site-packages/urllib3/util/retry.py", line 550, in increment
    raise six.reraise(type(error), error, _stacktrace)
  File "/home/airflow/.local/lib/python3.7/site-packages/urllib3/packages/six.py", line 769, in reraise
    raise value.with_traceback(tb)
  File "/home/airflow/.local/lib/python3.7/site-packages/urllib3/connectionpool.py", line 710, in urlopen
    chunked=chunked,
  File "/home/airflow/.local/lib/python3.7/site-packages/urllib3/connectionpool.py", line 449, in _make_request
    six.raise_from(e, None)
  File "<string>", line 3, in raise_from
  File "/home/airflow/.local/lib/python3.7/site-packages/urllib3/connectionpool.py", line 444, in _make_request
    httplib_response = conn.getresponse()
  File "/usr/local/lib/python3.7/http/client.py", line 1373, in getresponse
    response.begin()
  File "/usr/local/lib/python3.7/http/client.py", line 319, in begin
    version, status, reason = self._read_status()
  File "/usr/local/lib/python3.7/http/client.py", line 288, in _read_status
    raise RemoteDisconnected("Remote end closed connection without"
urllib3.exceptions.ProtocolError: ('Connection aborted.', RemoteDisconnected('Remote end closed connection without response'))

During handling of the above exception, another exception occurred:

Traceback (most recent call last):
  File "/home/airflow/.local/lib/python3.7/site-packages/airflow/operators/python.py", line 175, in execute
    return_value = self.execute_callable()
  File "/home/airflow/.local/lib/python3.7/site-packages/airflow/operators/python.py", line 192, in execute_callable
    return self.python_callable(*self.op_args, **self.op_kwargs)
  File "/opt/airflow/dags/src/extract.py", line 105, in get_artist_info
    r = requests.get(BASE_URL + 'artists/' + id, headers=headers)
  File "/home/airflow/.local/lib/python3.7/site-packages/requests/api.py", line 73, in get
    return request("get", url, params=params, **kwargs)
  File "/home/airflow/.local/lib/python3.7/site-packages/requests/api.py", line 59, in request
    return session.request(method=method, url=url, **kwargs)
  File "/home/airflow/.local/lib/python3.7/site-packages/requests/sessions.py", line 587, in request
    resp = self.send(prep, **send_kwargs)
  File "/home/airflow/.local/lib/python3.7/site-packages/requests/sessions.py", line 701, in send
    r = adapter.send(request, **kwargs)
  File "/home/airflow/.local/lib/python3.7/site-packages/requests/adapters.py", line 547, in send
    raise ConnectionError(err, request=request)
requests.exceptions.ConnectionError: ('Connection aborted.', RemoteDisconnected('Remote end closed connection without response'))
[2023-03-16T05:01:44.907+0000] {taskinstance.py:1323} INFO - Marking task as UP_FOR_RETRY. dag_id=Spotify_Data_ETL, task_id=GetArtistInfo, execution_date=20230316T042558, start_date=20230316T050108, end_date=20230316T050144
[2023-03-16T05:01:44.914+0000] {standard_task_runner.py:105} ERROR - Failed to execute job 1158 for task GetArtistInfo (('Connection aborted.', RemoteDisconnected('Remote end closed connection without response')); 8332)
[2023-03-16T05:01:44.962+0000] {local_task_job.py:208} INFO - Task exited with return code 1
[2023-03-16T05:01:44.982+0000] {taskinstance.py:2578} INFO - 0 downstream tasks scheduled from follow-on schedule check
